Workbook
Name Color: [1]Hoja1!$A$2:$A$4
Name CONVENCION: INDIRECT(#REF!)
Name MATRIZ: #REF!
Name MATRIZ: #REF!
Name MATRIZ: #REF!
Name MATRIZ: #REF!
Name MATRIZ: #REF!
Name MATRIZ: #REF!
Name MATRIZ: #REF!
Name MATRIZ: #REF!
Name MATRIZ: #REF!
Name MATRIZ: #REF!
Name MATRIZ: #REF!
Name MATRIZ: #REF!

Sheet Plantilla
D1: FORMATO | L1: Codigo: | N1: FOR-CA-012
D2: FICHA TECNICA DEL INDICADOR | L2: Versión: | N2: 3
L3: Fecha: | N3: 45099
B5: PROCESO: | D5: Administración de personal | H5: RESPONSABLE: | J5: =+VLOOKUP(D5,List!G:I,3,) -> Sandra Enriquez
B7: NOMBRE DEL INDICADOR | E7: =+VLOOKUP($O$10,#REF!,3,0) -> #REF!
B8: OBJETIVO DEL INDICADOR | E8: =+VLOOKUP($O$10,#REF!,4,0) -> #REF!
B9: FORMULA | E9: =+VLOOKUP($O$10,#REF!,5,0) -> #REF!
B10: Tipo de Indicador | C10: =+VLOOKUP($O$10,#REF!,6,0) -> #REF! | F10: Tendencia del indicador | I10: =+VLOOKUP($O$10,#REF!,9,0) -> #REF! | L10: Numero del Indicador | O10: 3
B11: Perspectiva | C11: =+VLOOKUP(O10,#REF!,16,0) -> #REF! | F11: Objetivo Estrategico | I11: =+VLOOKUP(O10,#REF!,17,0) -> #REF!
B12: DATOS DE LAS VARIABLES
C13: Nombre y Definición de la Variable | J13: Origen de Datos [Fuente] | M13: Frecuencia de Medición
B14: Variable 1 | C14: Total de retiros marcados extemporáneamente (3 días hábiles) | J14: (Fuente de donde se obtiene la información para alimentar el indicador) | M14: =+VLOOKUP($O$10,#REF!,7,0) -> #REF!
B15: Variable 2 | C15: (Total retiros marcados en el mes)
B16: MECANISMO Y RESPONSABLE DE MEDICIÓN
B17: Jefe de proceso y Coordinador SGI, realizará el calculo y análisis
B18: COMO SE INTERPRETA
B20: PERSONAS QUE DEBEN CONOCER EL RESULTADO
B21: Gerencia, coordinadores, Analistas, Auxiliar Etc.
B22: RESULTADOS
C23: Ene | D23: Feb | E23: Mar | F23: Abr | G23: May | H23: Jun | I23: Jul | J23: Ago | K23: Sept | L23: Oct | M23: Nov | N23: Dic | O23: Acum Año
B24: =+C14 -> Total de retiros marcados extemporáneamente (3 días hábiles) | C24: =+DB_Indicadores!F7 -> 1 | D24: 2945 | E24: 3590 | F24: 1636 | G24: 1630 | H24: 326 | I24: 1705 | J24: 1660 | K24: 1986 | L24: 1608 | O24: =SUM(C24:N24) -> 17087
B25: =+C15 -> (Total retiros marcados en el mes) | C25: =+DB_Indicadores!F8 -> 70 | D25: 180478 | E25: 188395 | F25: 219141 | G25: 216946 | H25: 220456 | I25: 199380 | J25: 238454 | K25: 167861 | L25: 175829 | O25: =SUM(C25:N25) -> 1807010
B26: Cumplimiento | C26: =+IFERROR(AVERAGE(C24/C25),"") -> 0.014285714 | D26: =+IFERROR(AVERAGE(D24/D25),"") -> 0.016317778 | E26: =+IFERROR(AVERAGE(E24/E25),"") -> 0.019055707 | F26: =+IFERROR(AVERAGE(F24/F25),"") -> 0.0074655131 | G26: =+IFERROR(AVERAGE(G24/G25),"") -> 0.0075133904 | H26: =+IFERROR(AVERAGE(H24/H25),"") -> 0.0014787531 | I26: =+IFERROR(AVERAGE(I24/I25),"") -> 0.0085515097 | J26: =+IFERROR(AVERAGE(J24/J25),"") -> 0.0069615104 | ... O26: =+IFERROR(AVERAGE(O24/O25),"") -> 0.0094559521
B27: Meta | C27: 0.02 | D27: =+$C$27 -> 0.02 | E27: =+$C$27 -> 0.02 | F27: =+$C$27 -> 0.02 | G27: =+$C$27 -> 0.02 | H27: =+$C$27 -> 0.02 | I27: =+$C$27 -> 0.02 | J27: =+$C$27 -> 0.02 | K27: =+$C$27 -> 0.02 | ... O27: =+$C$27 -> 0.02
B28: Cumplió Meta | C28: =+IF(C26<=C27,"Cumple","No Cumple") -> Cumple | D28: =+IF(D26<=D27,"Cumple","No Cumple") -> Cumple | E28: =+IF(E26<=E27,"Cumple","No Cumple") -> Cumple | F28: =+IF(F26<=F27,"Cumple","No Cumple") -> Cumple | G28: =+IF(G26<=G27,"Cumple","No Cumple") -> Cumple | H28: =+IF(H26<=H27,"Cumple","No Cumple") -> Cumple | I28: =+IF(I26<=I27,"Cumple","No Cumple") -> Cumple | J28: =+IF(J26<=J27,"Cumple","No Cumple") -> Cumple | ... O28: =+IF(O26<=O27,"Cumple","No Cumple") -> Cumple
B29: GRÁFICO DE RESULTADO
B42: ACCIONES CORRECTIVAS EN CASO DE NO CUMPLIR LA META
B43: CAUSAS DE NO CUMPLIMIENTO [Aplique metodologia de los 5 porque] | F43: PLAN DE ACCIONES | K43: RESPONSABLE | M43: FECHA DE CIERRE | N43: ESTADO
A44: 1 | B44: Explicación del porque se obtuvieron los resultados del indicador y Analisis de causa en el caso tal de no alcanzar la meta) Nota: Para el analisis de causas se recomienda usar la metodologia de los 5 porque para encontrar la causa raiz del no cunplimeinto del indicador. | F44: (Definir el plan de accion que se realizará para alcanzar la meta en los casos que el resultado del indicador no la cumpla)
A45: 2
A46: 3
A47: 4

Sheet Control de cambios
C2: FORMATO | F2: Código: | G2: FOR-CA-012
C3: CONTROL DOCUMENTAL | F3: Versión: | G3: 3
F4: Fecha: | G4: 45099
B6: Versión | C6: Cambios realizados | F6: Fecha
B7: 3 | C7: Actualización del documento y cambio de codificación | F7: 45099
B9: Elaboró | D9: Revisó | E9: Aprobó
B10: Nombre: Cristhian Palta | D10: Nombre: Catherin Pabón | E10: Nombre: Catherin Pabón
B11: Cargo: Analista de calidad | D11: Cargo: Coordinadora de auditoria y procesos | E11: Cargo: Coordinadora de auditoria y procesos

Sheet List
A1: ESTADO | B1: TIPO DE INDICADOR | C1: PERSPECTIVA | D1: TENDENCIA | E1: Objetivos estratégicos | F1: Frecuencia | G1: Procesos | H1: Cmpañia | I1: Responsable
A2: ABIERTO | B2: RESULTADO | C2: Servicio Diferencial | D2: Positiva | E2: Incrementar la UAI de la organización | F2: Mensual | G2: Direccionamiento estratégico | H2: Proservis Temporales | I2: Angela Gomez
A3: CERRADO | B3: DESEMPEÑO | C3: Crecimiento Rentable | D3: Negativa | E3: Disminución del gasto financiero | F3: Bimensual | G3: Gestión integral | H3: Proservis Generales | I3: Catherine Pabón
A4: EN PROCESO | B4: GESTIÓN | C4: Efectividad Operacional | E4: Incrementar la venta de los servicios | F4: Trimestral | G4: Proyectos y TICs | H4: PT & PG | I4: Cristian Castaño
C5: Gestión Personas | E5: Índice de satisfacción clientes | F5: Cuatrimestral | G5: Innovación y experiencias | I5: Juliana Franco
E6: Cumplimiento de ANS | F6: Semestral | G6: Gestión comercial | I6: Diego Sanchez
E7: Retención de clientes | F7: Anual | G7: Administración de personal | I7: Sandra Enriquez
E8: Nivel de productividad | G8: Selección y contratación | I8: Sandra Enriquez
E9: Eficacia en el logro de resultados | G9: Nomina y seguridad social | I9: Jhon Romero
E10: Implemenatación TD | G10: Seguridad y salud en el trabajo | I10: Cristina Truque
E11: Retención de personal | G11: Gestión humana | I11: Daniela Martinez
E12: Nivel de desempeño | G12: Compras | I12: Hassan Quinto
E13: Indice de cultura | G13: Tesorería | I13: Hassan Quinto
G14: Contabilidad | I14: Angelica Ramos
G15: Relaciones laborales | I15: Daniela Martinez
G16: Selección Especializada | I16: Sandra Enriquez

Sheet 0. Activos
D1: FORMATO
D2: FICHA TECNICA DEL INDICADOR
B5: PROCESO: | D5: Seguridad y Salud en el Trabajo | H5: RESPONSABLE: | J5: Johan Cartagena
B7: NOMBRE DEL INDICADOR | E7: Activos a nivel nacional
B8: DEFINICION | E8: NA
B9: FORMULA | E9: NA
B10: INTERPRETACION | E10: NA | Q10: 2026 | R10: 2025
B11: MECANISMO Y RESPONSABLE DE MEDICIÓN | Q11: 70
B12: Jefe de proceso y Coordinador SGI, realizará el calculo y análisis | Q12: 73 | R12: 102
B13: PERSONAS QUE DEBEN CONOCER EL RESULTADO | Q13: 71 | R13: 144
B14: Director SG SST - Gestor de Seguridad - Incubadora Santander SA | Q14: 81 | R14: 149
B15: RESULTADOS | R15: 189
C16: Ene | D16: Feb | E16: Mar | F16: Abr | G16: May | H16: Jun | I16: Jul | J16: Ago | K16: Sept | L16: Oct | M16: Nov | N16: Dic | O16: PROMEDIO | R16: 185
B17: 2026 | C17: 70 | D17: 73 | E17: 71 | F17: 81 | G17: 75 | H17: 80 | I17: 99 | J17: 99 | R17: 152
B18: 2025 | C18: 162 | D18: 116 | E18: 103 | F18: 120 | G18: 180 | H18: 175 | I18: 191 | J18: 194 | K18: 237 | L18: 215 | M18: 242 | N18: 287 | R18: 138
B19: GRÁFICO DE RESULTADO | R19: 237
R20: 215
R21: 242
B32: OBSERVACIONES
D35: FORMATO
D36: FICHA TECNICA DEL INDICADOR
B39: PROCESO: | D39: Seguridad y salud en el trabajo | H39: RESPONSABLE: | J39: Johan Cartagena
B41: NOMBRE DEL INDICADOR | E41: Activos sede cauca
B42: DEFINICION | E42: NA
B43: FORMULA | E43: NA
B44: INTERPRETACION | E44: NA
B45: MECANISMO Y RESPONSABLE DE MEDICIÓN
B46: Jefe de proceso y Coordinador SGI, realizará el calculo y análisis
B47: PERSONAS QUE DEBEN CONOCER EL RESULTADO
B48: Director SG SST - Gestor de Seguridad - Incubadora Santander SA
B49: RESULTADOS
B50: VARIABLE | C50: Ene | D50: Feb | E50: Mar | F50: Abr | G50: May | H50: Jun | I50: Jul | J50: Ago | K50: Sept | L50: Oct | M50: Nov | N50: Dic | O50: Acum Año
B51: 2025 | C51: 47 | D51: 38 | E51: 144 | F51: 32 | G51: 83 | H51: 86 | I51: 52 | J51: 33 | K51: 41 | L51: 90 | M51: 101 | N51: 54
B52: 2026 | C52: 7 | D52: 15 | E52: 15 | F52: 24 | G52: 22 | H52: 20
B53: GRÁFICO DE RESULTADO
B66: OBSERVACIONES
D69: FORMATO
D70: FICHA TECNICA DEL INDICADOR
B73: PROCESO: | D73: Seguridad y Salud en el Trabajo | H73: RESPONSABLE: | J73: Johan Cartagena
B75: NOMBRE DEL INDICADOR | E75: Activos sede santander
...

Sheet 14. # AT x Mes
D1: FORMATO
D2: FICHA TECNICA DEL INDICADOR
B5: PROCESO: | D5: Seguridad y Salud en el Trabajo | H5: RESPONSABLE: | J5: Johan Cartagena
B7: NOMBRE DEL INDICADOR | E7: Tasa de accidentabilidad sede cauca
B8: DEFINICION | E8: Numero de veces que ocurre un accidente de trabajo en el mes
B9: FORMULA | E9: (Numero de accidentes de trabajo que se presentaron en el mes / Numero de trabajadores en el mes)*100
B10: INTERPRETACION | E10: Por cada cien trabajadores que laboraron en el mes, se presentaron X accidentes de trabajo
B11: MECANISMO Y RESPONSABLE DE MEDICIÓN
B12: Jefe de proceso y Coordinador SGI, realizará el calculo y análisis
B13: PERSONAS QUE DEBEN CONOCER EL RESULTADO
B14: Director SG SST - Gestor de Seguridad - Incubadora Santander SA
B15: RESULTADOS
B16: VARIABLE | C16: Ene | D16: Feb | E16: Mar | F16: Abr | G16: May | H16: Jun | I16: Jul | J16: Ago | K16: Sept | L16: Oct | M16: Nov | N16: Dic | O16: Acum Año
B17: # AT por Mes 2026 | C17: 1 | D17: 3 | E17: 0 | F17: 1 | G17: 0 | H17: 2 | I17: 1 | J17: 4
B18: # AT por Mes 2025 | C18: 3 | D18: 4 | E18: 4 | F18: 2 | G18: 4 | H18: 5 | I18: 5 | J18: 1 | K18: 3 | L18: 3 | M18: 5 | N18: 1
B19: GRÁFICO DE RESULTADO
B32: OBERVACIONES
B33: En octubre de 2025 se reportaron 3 accidentes de trabajo, frente a los 4 casos registrados en octubre de 2024. Por su parte, en noviembre de 2025 se reportaron 5 accidentes de trabajo, frente a los 4 casos registrados en noviembre de 2024.

Sheet DB_Indicadores
D2: FORMATO
D3: FICHA TECNICA DEL INDICADOR BASE DE DATOS PARA LOS INDICADORES
B6: N° | C6: Indicador | D6: Datos | E6: Meta | F6: Ene | G6: Feb | H6: Mar | I6: Abr | J6: May | K6: Jun | L6: Jul | M6: Ago | N6: Sep | O6: Oct | P6: Nov | Q6: Dic | R6: PROMEDIO AÑO | S6: PROMEDIO TASA AÑO
B7: 1 | C7: Tasa de accidentabilidad a nivel nacional | D7: Numero de accidentes de trabajo que se presentaron en el mes | E7: NA | F7: ='1. Tas. Nacional'!C17 -> 1 | G7: ='1. Tas. Nacional'!D17 -> 5 | H7: ='1. Tas. Nacional'!E17 -> 0 | I7: 2 | J7: 4 | K7: 5 | L7: 5 | M7: 1 | N7: 3 | O7: 3 | P7: 5 | Q7: ='1. Tas. Nacional'!$N$17 -> 0 | R7: =SUM(F7:Q7) -> 34 | S7: =AVERAGE(F10:Q10) -> #DIV/0!
D8: Numero de trabajadores en el mes | F8: ='1. Tas. Nacional'!C18 -> 70 | G8: ='1. Tas. Nacional'!D18 -> 73 | H8: ='1. Tas. Nacional'!E18 -> 71 | I8: 149 | J8: 189 | K8: 185 | L8: 152 | M8: 138 | N8: 148 | O8: 173 | P8: 167 | Q8: ='1. Tas. Nacional'!$N$18 -> 0 | R8: =AVERAGE(F8:Q8) -> 126.25
D10: Resultado | F10: =F7/F8*100 -> 1.4285714 | G10: =G7/G8*100 -> 6.8493151 | H10: =H7/H8*100 -> 0 | I10: =I7/I8*100 -> 1.3422819 | J10: =J7/J8*100 -> 2.1164021 | K10: =K7/K8*100 -> 2.7027027 | L10: =L7/L8*100 -> 3.2894737 | M10: =M7/M8*100 -> 0.72463768 | ... Q10: =Q7/Q8*100 -> #DIV/0!
B11: 2 | C11: Tasa de accidentabilidad sede cauca | D11: Numero de accidentes de trabajo que se presentaron en el mes | E11: NA | F11: ='2. Tas. Cauca'!C17 -> 0 | G11: ='2. Tas. Cauca'!D17 -> 0 | H11: ='2. Tas. Cauca'!E17 -> 0 | I11: ='2. Tas. Cauca'!F17 -> 0 | J11: 2 | K11: 2 | L11: 2 | M11: ='2. Tas. Cauca'!J17 -> 0 | N11: ='2. Tas. Cauca'!K17 -> 0 | O11: 2 | P11: 0 | Q11: ='2. Tas. Cauca'!N17 -> 0 | R11: =SUM(F11:Q11) -> 8 | S11: =AVERAGE(F14:Q14) -> #DIV/0!
D12: Numero de trabajadores en el mes | F12: ='2. Tas. Cauca'!C18 -> 7 | G12: ='2. Tas. Cauca'!D18 -> 15 | H12: ='2. Tas. Cauca'!E18 -> 15 | I12: 32 | J12: 83 | K12: 86 | L12: 52 | M12: 33 | N12: 41 | O12: 90 | P12: 101 | Q12: ='2. Tas. Cauca'!N18 -> 0 | R12: =AVERAGE(F12:Q12) -> 46.25
D14: Resultado | F14: =F11/F12*100 -> 0 | G14: =G11/G12*100 -> 0 | H14: =H11/H12*100 -> 0 | I14: =I11/I12*100 -> 0 | J14: =J11/J12*100 -> 2.4096386 | K14: =K11/K12*100 -> 2.3255814 | L14: =L11/L12*100 -> 3.8461538 | M14: =M11/M12*100 -> 0 | ... Q14: =Q11/Q12*100 -> #DIV/0!
B15: 3 | C15: Tasa de accidentabilidad sede santander | D15: Numero de accidentes de trabajo que se presentaron en el mes | E15: NA | F15: ='3. Tas. Santander'!C17 -> 1 | G15: ='3. Tas. Santander'!D17 -> 5 | H15: ='3. Tas. Santander'!E17 -> 0 | I15: 2 | J15: 2 | K15: 3 | L15: 3 | M15: 1 | N15: 3 | O15: 1 | P15: 5 | Q15: ='3. Tas. Santander'!N17 -> 0 | R15: =SUM(F15:Q15) -> 26 | S15: =AVERAGE(F18:Q18) -> #DIV/0!
D16: Numero de trabajadores en el mes | F16: ='3. Tas. Santander'!C18 -> 57 | G16: ='3. Tas. Santander'!D18 -> 51 | H16: ='3. Tas. Santander'!E18 -> 48 | I16: 113 | J16: 102 | K16: 94 | L16: 92 | M16: 94 | N16: 99 | O16: 76 | P16: 59 | Q16: ='3. Tas. Santander'!N18 -> 0 | R16: =AVERAGE(F16:Q16) -> 73.75
D18: Resultado | F18: =F15/F16*100 -> 1.754386 | G18: =G15/G16*100 -> 9.8039216 | H18: =H15/H16*100 -> 0 | I18: =I15/I16*100 -> 1.7699115 | J18: =J15/J16*100 -> 1.9607843 | K18: =K15/K16*100 -> 3.1914894 | L18: =L15/L16*100 -> 3.2608696 | M18: =M15/M16*100 -> 1.0638298 | ... Q18: =Q15/Q16*100 -> #DIV/0!
B19: 4 | C19: Severidad de accidentabilidad a nivel nacional | D19: Numero de dias de incapacidad por accidente de trabajo en el mes | E19: NA | F19: ='4. Sev. Nacional'!#REF! -> #REF! | G19: ='4. Sev. Nacional'!#REF! -> #REF! | H19: 13 | I19: 9 | J19: 15 | K19: 28 | L19: 71 | M19: 4 | N19: 2 | O19: 16 | P19: 10 | Q19: ='4. Sev. Nacional'!#REF! -> #REF!
D20: Numero de trabajadores en el mes | F20: ='4. Sev. Nacional'!C18 -> 70 | G20: ='4. Sev. Nacional'!D18 -> 51 | H20: ='4. Sev. Nacional'!E18 -> 71 | I20: 149 | J20: 189 | K20: 185 | L20: 152 | M20: 138 | N20: 148 | O20: ='4. Sev. Nacional'!L18 -> 0 | P20: 167 | Q20: ='4. Sev. Nacional'!N18 -> 0
D21: Resultado | F21: =F19/F20*100 -> #REF! | G21: =G19/G20*100 -> #REF! | H21: =H19/H20*100 -> 18.309859 | I21: =I19/I20*100 -> 6.0402685 | J21: =J19/J20*100 -> 7.9365079 | K21: =K19/K20*100 -> 15.135135 | L21: =L19/L20*100 -> 46.710526 | M21: =M19/M20*100 -> 2.8985507 | ... Q21: =Q19/Q20*100 -> #REF!
B22: 5 | C22: Severidad de accidentabilidad sede cauca | D22: Numero de dias de incapacidad por accidente de trabajo en el mes | E22: NA | F22: ='5. Sev. Cauca'!C17 -> 0 | G22: ='5. Sev. Cauca'!D17 -> 0 | H22: ='5. Sev. Cauca'!E17 -> 0 | I22: ='5. Sev. Cauca'!F17 -> 0 | J22: 15 | K22: 4 | L22: 35 | M22: ='5. Sev. Cauca'!J17 -> 0 | N22: ='5. Sev. Cauca'!K17 -> 0 | O22: 11 | P22: ='5. Sev. Cauca'!M17 -> 0 | Q22: ='5. Sev. Cauca'!N17 -> 0
D23: Numero de trabajadores en el mes | F23: ='5. Sev. Cauca'!C18 -> 7 | G23: ='5. Sev. Cauca'!D18 -> 15 | H23: ='5. Sev. Cauca'!E18 -> 15 | I23: 32 | J23: 83 | K23: 86 | L23: 52 | M23: 33 | N23: 41 | O23: ='5. Sev. Cauca'!L18 -> 0 | P23: 101 | Q23: ='5. Sev. Cauca'!N18 -> 0
D25: Resultado | F25: =F22/F23*100 -> 0 | G25: =G22/G23*100 -> 0 | H25: =H22/H23*100 -> 0 | I25: =I22/I23*100 -> 0 | J25: =J22/J23*100 -> 18.072289 | K25: =K22/K23*100 -> 4.6511628 | L25: =L22/L23*100 -> 67.307692 | M25: =M22/M23*100 -> 0 | ... Q25: =Q22/Q23*100 -> #DIV/0!
B26: 6 | C26: Severidad de accidentabilidad sede santander | D26: Numero de dias de incapacidad por accidente de trabajo en el mes | E26: NA | F26: ='6. Sev. Santander'!C17 -> 3 | G26: ='6. Sev. Santander'!D17 -> 41 | H26: ='6. Sev. Santander'!E17 -> 0 | I26: 9 | J26: 0 | K26: 39 | L26: 36 | M26: 4 | N26: 2 | O26: 5 | P26: 10 | Q26: ='6. Sev. Santander'!N17 -> 0
D27: Numero de trabajadores en el mes | F27: ='6. Sev. Santander'!C18 -> 57 | G27: ='6. Sev. Santander'!D18 -> 51 | H27: ='6. Sev. Santander'!E18 -> 48 | I27: 113 | J27: 102 | K27: 94 | L27: 92 | M27: 94 | N27: 99 | O27: 76 | P27: 59 | Q27: ='6. Sev. Santander'!N18 -> 0
D28: Resultado | F28: =F26/F27*100 -> 5.2631579 | G28: =G26/G27*100 -> 80.392157 | H28: =H26/H27*100 -> 0 | I28: =I26/I27*100 -> 7.9646018 | J28: =J26/J27*100 -> 0 | K28: =K26/K27*100 -> 41.489362 | L28: =L26/L27*100 -> 39.130435 | M28: =M26/M27*100 -> 4.2553191 | ... Q28: =Q26/Q27*100 -> #DIV/0!
B29: 7 | C29: Cumplimiento de investigacion de accidentes de trabajo | D29: Numero de accidentes de trabajo investigado | E29: 1 | F29: ='7. Inves. AT'!C18 -> 1 | G29: ='7. Inves. AT'!D18 -> 5 | H29: 4 | I29: 2 | J29: 4 | K29: 5 | L29: 5 | M29: 1 | N29: 3 | O29: 2 | P29: 5 | Q29: ='7. Inves. AT'!N18 -> 0
D30: Numero de accidentes de trabajo ocurrido | F30: ='7. Inves. AT'!C17 -> 1 | G30: ='7. Inves. AT'!D17 -> 5 | H30: 4 | I30: 2 | J30: 4 | K30: 5 | L30: 5 | M30: 1 | N30: 3 | O30: 2 | P30: 5 | Q30: ='7. Inves. AT'!N17 -> 0
D31: Resultado | F31: =F29/F30*100 -> 100 | G31: =G29/G30*100 -> 100 | H31: =H29/H30*100 -> 100 | I31: =I29/I30*100 -> 100 | J31: =J29/J30*100 -> 100 | K31: =K29/K30*100 -> 100 | L31: =L29/L30*100 -> 100 | M31: =M29/M30*100 -> 100 | ... Q31: =Q29/Q30*100 -> #DIV/0!
D32: Meta | F32: 1 | G32: 1 | H32: 1 | I32: 1 | J32: 1 | K32: 1 | L32: 1 | M32: 1 | N32: 1 | O32: 1 | P32: 1 | Q32: 1
B33: 8 | C33: Cumplimiento de ejecucion planes de accion | D33: Numero de planes de accion ejecutado | E33: 1 | F33: ='13. Ejecu. PA'!C17 -> 1 | G33: ='13. Ejecu. PA'!D17 -> 0 | H33: ='13. Ejecu. PA'!E17 -> 0 | I33: 1 | J33: 1 | K33: ='13. Ejecu. PA'!H17 -> 0 | L33: 13 | M33: 2 | N33: 7 | O33: 4 | P33: 0 | Q33: ='13. Ejecu. PA'!N17 -> 0
D34: Numero de planes de accion planeados | F34: ='13. Ejecu. PA'!C18 -> 0 | G34: ='13. Ejecu. PA'!D18 -> 0 | H34: ='13. Ejecu. PA'!E18 -> 0 | I34: 2 | J34: 4 | K34: 5 | L34: ='13. Ejecu. PA'!I18 -> 0 | M34: 2 | N34: 7 | O34: 4 | P34: 10 | Q34: ='13. Ejecu. PA'!N18 -> 0
D35: Resultado | F35: =F33/F34*100 -> #DIV/0! | G35: =G33/G34*100 -> #DIV/0! | H35: =H33/H34*100 -> #DIV/0! | I35: =I33/I34*100 -> 50 | J35: =J33/J34*100 -> 25 | K35: =K33/K34*100 -> 0 | L35: =L33/L34*100 -> #DIV/0! | M35: =M33/M34*100 -> 100 | ... Q35: =Q33/Q34*100 -> #DIV/0!
D36: Meta | F36: 1 | G36: 1 | H36: 1 | I36: 1 | J36: 1 | K36: 1 | L36: 1 | M36: 1 | N36: 1 | O36: 1 | P36: 1 | Q36: 1
B37: 9 | C37: Activos nivel nacional | D37: 2024 | E37: NA | F37: ='0. Activos'!C17 -> 70 | G37: ='0. Activos'!D17 -> 73 | H37: ='0. Activos'!E17 -> 71 | I37: ='0. Activos'!F17 -> 81 | J37: 189 | K37: ='0. Activos'!H17 -> 80 | L37: 191 | M37: ='0. Activos'!J17 -> 99 | N37: 148 | O37: ='0. Activos'!L17 -> 0 | P37: ='0. Activos'!M17 -> 0 | Q37: ='0. Activos'!N17 -> 0
D38: 2025 | F38: ='0. Activos'!C18 -> 162 | G38: ='0. Activos'!D18 -> 116 | H38: ='0. Activos'!E18 -> 103 | I38: ='0. Activos'!F18 -> 120 | J38: 180 | K38: ='0. Activos'!H18 -> 175 | L38: ='0. Activos'!I18 -> 191 | M38: ='0. Activos'!J18 -> 194 | N38: 237 | O38: ='0. Activos'!L18 -> 215 | P38: ='0. Activos'!M18 -> 242 | Q38: ='0. Activos'!N18 -> 287
B39: 10 | C39: Activos sede cauca | D39: 2024 | E39: NA | F39: ='0. Activos'!C51 -> 47 | G39: ='0. Activos'!D51 -> 38 | H39: ='0. Activos'!E51 -> 144 | I39: ='0. Activos'!F51 -> 32 | J39: 83 | K39: ='0. Activos'!H51 -> 86 | L39: ='0. Activos'!I51 -> 52 | M39: ='0. Activos'!J51 -> 33 | N39: 41 | O39: ='0. Activos'!L51 -> 90 | P39: ='0. Activos'!M51 -> 101 | Q39: ='0. Activos'!N51 -> 54
D40: 2025 | F40: ='0. Activos'!C52 -> 7 | G40: ='0. Activos'!D52 -> 15 | H40: ='0. Activos'!E52 -> 15 | I40: ='0. Activos'!F52 -> 24 | J40: 73 | K40: ='0. Activos'!H52 -> 20 | L40: ='0. Activos'!I52 -> 0 | M40: ='0. Activos'!J52 -> 0 | N40: 90 | O40: ='0. Activos'!L52 -> 0 | P40: ='0. Activos'!M52 -> 0 | Q40: ='0. Activos'!N52 -> 0
B41: 11 | C41: Activos sede santander | D41: 2025 | E41: NA | F41: ='0. Activos'!C85 -> 57 | G41: ='0. Activos'!D85 -> 51 | H41: ='0. Activos'!E85 -> 48 | I41: ='0. Activos'!F85 -> 50 | J41: ='0. Activos'!G85 -> 47 | K41: ='0. Activos'!H85 -> 51 | L41: ='0. Activos'!I85 -> 0 | M41: ='0. Activos'!J85 -> 0 | ... Q41: ='0. Activos'!N85 -> 0
D42: 2024 | F42: ='0. Activos'!C86 -> 68 | G42: ='0. Activos'!D86 -> 64 | H42: ='0. Activos'!E86 -> 111 | I42: ='0. Activos'!F86 -> 113 | J42: ='0. Activos'!G86 -> 102 | K42: ='0. Activos'!H86 -> 94 | L42: ='0. Activos'!I86 -> 92 | M42: ='0. Activos'!J86 -> 94 | ... Q42: ='0. Activos'!N86 -> 37

Sheet 1. Tas. Nacional
D1: FORMATO
D2: FICHA TECNICA DEL INDICADOR
B5: PROCESO: | D5: Seguridad y Salud en el Trabajo | H5: RESPONSABLE: | J5: Luis Acosta
B7: NOMBRE DEL INDICADOR | E7: Tasa de accidentabilidad nacional
B8: DEFINICION | E8: Numero de veces que ocurre un accidente de trabajo en el mes
B9: FORMULA | E9: (Numero de accidentes de trabajo que se presentaron en el mes / Numero de trabajadores en el mes)*100
B10: INTERPRETACION | E10: Por cada cien trabajadores que laboraron en el mes, se presentaron X accidentes de trabajo
B11: MECANISMO Y RESPONSABLE DE MEDICIÓN
B12: Jefe de proceso y Coordinador SGI, realizará el calculo y análisis
B13: PERSONAS QUE DEBEN CONOCER EL RESULTADO
B14: Director SG SST - Gestor de Seguridad - Incubadora Santander SA
B15: RESULTADOS
B16: VARIABLE | C16: Ene | D16: Feb | E16: Mar | F16: Abr | G16: May | H16: Jun | I16: Jul | J16: Ago | K16: Sept | L16: Oct | M16: Nov | N16: Dic | O16: Acum Año
B17: #AT en el mes | C17: 1 | D17: 5 | E17: 0 | F17: 1 | G17: 0 | H17: 2 | I17: 1 | J17: 4
B18: # Trabaj Act. En el mes | C18: 70 | D18: 73 | E18: 71 | F18: 81 | G18: 75 | H18: 80 | I18: 99 | J18: 99
B19: TASA 2026 | C19: =C17/C18*100 -> 1.4285714 | D19: =D17/D18*100 -> 6.8493151 | E19: =E17/E18*100 -> 0 | F19: =F17/F18*100 -> 1.2345679 | G19: =G17/G18*100 -> 0 | H19: =H17/H18*100 -> 2.5 | I19: =I17/I18*100 -> 1.010101 | J19: =J17/J18*100 -> 4.040404 | ... N19: =N17/N18*100 -> #DIV/0!
B20: TASA 2025 | C20: 1.23 | D20: 3.92 | E20: 2.78 | F20: 1.34 | G20: 2.12 | H20: 2.7 | I20: 3.29 | J20: 0.72 | K20: 2.03 | L20: 1.73 | M20: 2.99 | N20: 1.03
B21: GRÁFICO DE RESULTADO
B34: OBSERVACIONES
B35: Durante el mes de octubre de 2025 se presentaron dos (3) accidentes de trabajo, de los cuales dos ocurrieron en el departamento del Cauca y uno (1) en el departamento de Santander. En el mes de noviembre de 2025 se registraron cinco (5) accidentes de trabajo, todos en Santander. A todos los casos se les realizaron las respectivas investigaciones de accidentes de trabajo, elaborada por la Asesora de Prevención correspondiente: Liliana Lozano (Bucaramanga).

Sheet 2. Tas. Cauca
D1: FORMATO
D2: FICHA TECNICA DEL INDICADOR
B5: PROCESO: | D5: Seguridad y salud en el trabajo | H5: RESPONSABLE: | J5: Johan Cartagena
B7: NOMBRE DEL INDICADOR | E7: Tasa de accidentabilidad sede cauca
B8: DEFINICION | E8: Numero de veces que ocurre un accidente de trabajo en el mes
B9: FORMULA | E9: (Numero de accidentes de trabajo que se presentaron en el mes / Numero de trabajadores en el mes)*100
B10: INTERPRETACION | E10: Por cada cien trabajadores que laboraron en el mes, se presentaron X accidentes de trabajo
B11: MECANISMO Y RESPONSABLE DE MEDICIÓN
B12: Jefe de proceso y Coordinador SGI, realizará el calculo y análisis
B13: PERSONAS QUE DEBEN CONOCER EL RESULTADO
B14: Director SG SST - Gestor de Seguridad - Incubadora Santander SA
B15: RESULTADOS
B16: VARIABLE | C16: Ene | D16: Feb | E16: Mar | F16: Abr | G16: May | H16: Jun | I16: Jul | J16: Ago | K16: Sept | L16: Oct | M16: Nov | N16: Dic | O16: Acum Año
B17: #AT en el mes | C17: 0 | D17: 0 | E17: 0 | F17: 0 | G17: 0 | H17: 1 | I17: 0 | J17: 0
B18: # Trabaj Act. En el mes | C18: 7 | D18: 15 | E18: 15 | F18: 24 | G18: 22 | H18: 20 | I18: 11 | J18: 10
B19: TASA 2026 | C19: =C17/C18*100 -> 0 | D19: =D17/D18*100 -> 0 | E19: =E17/E18*100 -> 0 | F19: =F17/F18*100 -> 0 | G19: =G17/G18*100 -> 0 | H19: =H17/H18*100 -> 5 | I19: =I17/I18*100 -> 0 | J19: =J17/J18*100 -> 0 | ... N19: =N17/N18*100 -> #DIV/0!
B20: TASA 2025 | C20: 2.3 | D20: 5.3 | E20: 0 | F20: 0 | G20: 2.4 | H20: 2.3 | I20: 3.8 | J20: 0 | K20: 0 | L20: 2.2 | M20: 0 | N20: 0
B21: GRÁFICO DE RESULTADO
B34: OBERVACIONES
B35: Para el mes de octubre, se obtuvo una tasa de accidentalidad del 2,2%, evidenciando una reducción significativa en comparación con el mismo periodo del año 2024, cuando se reportó una tasa del 6,5%. En la zona del Cauca se notificó un (1) accidente de trabajo ocurrido el 31 de octubre de 2025, el cual fue debidamente reportado e investigado. Durante el mes de noviembre de 2025 no se registraron accidentes de trabajo en la zona del Cauca.

Sheet 3. Tas. Santander
D1: FORMATO
D2: FICHA TECNICA DEL INDICADOR
B5: PROCESO: | D5: Seguridad y salud en el trabajo | H5: RESPONSABLE: | J5: Johan Cartagena
B7: NOMBRE DEL INDICADOR | E7: Tasa de accidentabilidad sede santander
B8: DEFINICION | E8: Numero de veces que ocurre un accidente de trabajo en el mes
B9: FORMULA | E9: (Numero de accidentes de trabajo que se presentaron en el mes / Numero de trabajadores en el mes)*100
B10: INTERPRETACION | E10: Por cada cien trabajadores que laboraron en el mes, se presentaron X accidentes de trabajo
B11: MECANISMO Y RESPONSABLE DE MEDICIÓN
B12: Jefe de proceso y Coordinador SGI, realizará el calculo y análisis
B13: PERSONAS QUE DEBEN CONOCER EL RESULTADO
B14: Director SG SST - Gestor de Seguridad - Incubadora Santander SA
B15: RESULTADOS
B16: VARIABLE | C16: Ene | D16: Feb | E16: Mar | F16: Abr | G16: May | H16: Jun | I16: Jul | J16: Ago | K16: Sept | L16: Oct | M16: Nov | N16: Dic | O16: Acum Año
B17: #AT en el mes | C17: 1 | D17: 5 | E17: 0 | F17: 1 | G17: 0 | H17: 1 | I17: 1 | J17: 4
B18: # Trabaj Act. En el mes | C18: 57 | D18: 51 | E18: 48 | F18: 50 | G18: 47 | H18: 51 | I18: 81 | J18: 82
B19: TASA 2026 | C19: =C17/C18*100 -> 1.754386 | D19: =D17/D18*100 -> 9.8039216 | E19: =E17/E18*100 -> 0 | F19: =F17/F18*100 -> 2 | G19: =G17/G18*100 -> 0 | H19: =H17/H18*100 -> 1.9607843 | I19: =I17/I18*100 -> 1.2345679 | J19: =J17/J18*100 -> 4.8780488 | ... N19: =N17/N18*100 -> #DIV/0!
B20: TASA 2025 | C20: 5.9 | D20: 3.1 | E20: 3.6 | F20: 1.8 | G20: 2 | H20: 3.2 | I20: 3.3 | J20: 1.1 | K20: 3 | L20: 1.3 | M20: 8.5 | N20: 0
B21: GRÁFICO DE RESULTADO
B34: OBSERVACIONES
B35: Durante el mes de octubre de 2025 se registró una tasa de accidentalidad del 1,3%, valor que se mantiene igual al obtenido en el mismo periodo del año 2024. En la zona de Santander se presentó un (1) accidente de trabajo, ocurrido el 28 de octubre de 2025, el cual fue reportado e investigado. Durante el mes de noviembre de 2025, se registró una tasa de accidentalidad del 8,5%, lo que representa un incremento significativo frente al mismo periodo del año 2024, cuando la tasa fue del 1,8%. En la zona de Santander se reportaron cinco (5) accidentes de trabajo, ocurridos los días 13, 17, 18, 19 y 23 de noviembre de 2025. Todos los eventos fueron debidamente reportados ante la ARL Positiva y sujetos a investigación conforme a los procedimientos establecidos.

Sheet 4. Sev. Nacional
D1: FORMATO
D2: FICHA TECNICA DEL INDICADOR
B5: PROCESO: | D5: Seguridad y salud en el trabajo | H5: RESPONSABLE: | J5: Johan Cartagena
B7: NOMBRE DEL INDICADOR | E7: Severidad de accidentabilidad
B8: DEFINICION | E8: Numero de dias perdidos por accidentes de trabajo en el mes
B9: FORMULA | E9: (Numero de dias de incapacidad por accidente de trabajo en el mes / Numero de trabajadores en el mes)*100 | R9: >
B10: INTERPRETACION | E10: Por cada cien trabajadores que laboraron en el mes, se perdieron X dias por accidente de trabajo
B11: MECANISMO Y RESPONSABLE DE MEDICIÓN
B12: Jefe de proceso y Coordinador SGI, realizará el calculo y análisis
B13: PERSONAS QUE DEBEN CONOCER EL RESULTADO
B14: Director SG SST - Gestor de Seguridad - Incubadora Santander SA
B15: RESULTADOS | X15: 3
B16: VARIABLE | C16: Ene | D16: Feb | E16: Mar | F16: Abr | G16: May | H16: Jun | I16: Jul | J16: Ago | K16: Sept | L16: Oct | M16: Nov | N16: Dic | O16: Acum Año
B17: # Dias Incapa en el mes | C17: 3 | D17: 41 | E17: 0 | F17: 20 | G17: 0 | H17: 42 | I17: 37 | J17: 29
B18: # Trabajadores en el mes | C18: 70 | D18: 51 | E18: 71 | F18: 81 | G18: 75 | H18: 80 | I18: 99 | J18: 99
B19: SEVERIDAD 2026 | C19: =C17/C18*100 -> 4.2857143 | D19: =D17/D18*100 -> 80.392157 | E19: =E17/E18*100 -> 0 | F19: =F17/F18*100 -> 24.691358 | G19: =G17/G18*100 -> 0 | H19: =H17/H18*100 -> 52.5 | I19: =I17/I18*100 -> 37.373737 | J19: =J17/J18*100 -> 29.292929
B20: SEVERIDAD 2025 | C20: 10.3 | D20: 10.8 | E20: 9 | F20: 6 | G20: 7.9 | H20: 15.1 | I20: 46.7 | J20: 2.9 | K20: 1.4 | L20: 9.2 | M20: 6 | N20: 34
B21: GRÁFICO DE RESULTADO
B34: OBSERVACIONES
B35: En octubre de 2025, la severidad alcanzó el 9,2 %, mostrando también una reducción considerable en comparación con el 46,5 % reportado en octubre de 2024. A nivel nacional, la severidad en el mes de noviembre de 2025 fue del 6,0 %, lo que representa un aumento significativa frente al 1,6 % registrado en el mismo mes de 2024.

Sheet 5. Sev. Cauca
D1: FORMATO
D2: FICHA TECNICA DEL INDICADOR
B5: PROCESO: | D5: Seguridad y salud en el trabajo | H5: RESPONSABLE: | J5: Johan Cartagena
B7: NOMBRE DEL INDICADOR | E7: Severidad de accidentabilidad
B8: DEFINICION | E8: Numero de dias perdidos por accidentes de trabajo en el mes
B9: FORMULA | E9: (Numero de dias de incapacidad por accidente de trabajo en el mes / Numero de trabajadores en el mes)*100
B10: INTERPRETACION | E10: Por cada cien trabajadores que laboraron en el mes, se perdieron X dias por accidente de trabajo
B11: MECANISMO Y RESPONSABLE DE MEDICIÓN
B12: Jefe de proceso y Coordinador SGI, realizará el calculo y análisis
B13: PERSONAS QUE DEBEN CONOCER EL RESULTADO
B14: Director SG SST - Gestor de Seguridad - Incubadora Santander SA
B15: RESULTADOS
B16: VARIABLE | C16: Ene | D16: Feb | E16: Mar | F16: Abr | G16: May | H16: Jun | I16: Jul | J16: Ago | K16: Sept | L16: Oct | M16: Nov | N16: Dic | O16: Acum Año
B17: # Dias Incapa en el mes | C17: 0 | D17: 0 | E17: 0 | F17: 0 | G17: 0 | H17: 28 | I17: 30 | J17: 0
B18: # Trabajadores en el mes | C18: 7 | D18: 15 | E18: 15 | F18: 24 | G18: 22 | H18: 20 | I18: 11 | J18: 10
B19: SEVERIDAD 2026 | C19: =C17/C18*100 -> 0 | D19: =D17/D18*100 -> 0 | E19: =E17/E18*100 -> 0 | F19: =F17/F18*100 -> 0 | G19: =G17/G18*100 -> 0 | H19: =H17/H18*100 -> 140 | I19: =I17/I18*100 -> 272.72727 | J19: =J17/J18*100 -> 0 | ... M19: =M17/M18*100 -> #DIV/0!
B20: SEVERIDAD 2025 | C20: 3.4 | D20: 15.8 | E20: 30.3 | F20: 18.8 | G20: 18.1 | H20: 4.7 | I20: 67.3 | J20: 0 | K20: 0 | L20: 12.2 | M20: 0 | N20: 3.7
B21: GRÁFICO DE RESULTADO
B34: OBSERVACIONES
B35: En octubre de 2025 se registró una severidad del 12,2 %, frente al 115,2 % observado en el mismo mes de 2024, evidenciándose así una considerable reducción respecto al año anterior. En la sede Cauca, la severidad registrada en noviembre de 2025 fue del 0 %, lo que representa una disminución significativa en comparación con el 4,6 % reportado en noviembre de 2024.

Sheet 6. Sev. Santander
D1: FORMATO
D2: FICHA TECNICA DEL INDICADOR
B5: PROCESO: | D5: Seguridad y Salud en el Trabajo | H5: RESPONSABLE: | J5: Johan Cartagena
B7: NOMBRE DEL INDICADOR | E7: Severidad de accidentabilidad
B8: DEFINICION | E8: Numero de dias perdidos por accidentes de trabajo en el mes
B9: FORMULA | E9: (Numero de dias de incapacidad por accidente de trabajo en el mes / Numero de trabajadores en el mes)*100
B10: INTERPRETACION | E10: Por cada cien trabajadores que laboraron en el mes, se perdieron X dias por accidente de trabajo
B11: MECANISMO Y RESPONSABLE DE MEDICIÓN
B12: Jefe de proceso y Coordinador SGI, realizará el calculo y análisis
B13: PERSONAS QUE DEBEN CONOCER EL RESULTADO
B14: Director SG SST - Gestor de Seguridad - Incubadora Santander SA
B15: RESULTADOS
B16: VARIABLE | C16: Ene | D16: Feb | E16: Mar | F16: Abr | G16: May | H16: Jun | I16: Jul | J16: Ago | K16: Sept | L16: Oct | M16: Nov | N16: Dic | O16: Acum Año
B17: # Dias Incapa en el mes | C17: 3 | D17: 41 | E17: 0 | F17: 20 | G17: 0 | H17: 25 | I17: 7 | J17: 28
B18: # Trabajadores en el mes | C18: 57 | D18: 51 | E18: 48 | F18: 50 | G18: 47 | H18: 51 | I18: 81 | J18: 82
B19: SEVERIDAD 2026 | C19: =C17/C18*100 -> 5.2631579 | D19: =D17/D18*100 -> 80.392157 | E19: =E17/E18*100 -> 0 | F19: =F17/F18*100 -> 40 | G19: =G17/G18*100 -> 0 | H19: =H17/H18*100 -> 49.019608 | I19: =I17/I18*100 -> 8.6419753 | J19: =J17/J18*100 -> 34.146341
B20: SEVERIDAD 2025 | C20: 0 | D20: 10.9 | E20: 11.7 | F20: 8 | G20: 0 | H20: 41.5 | I20: 39.1 | J20: 4.3 | K20: 2 | L20: 6.6 | M20: 16.9 | N20: 0
B21: GRÁFICO DE RESULTADO
B34: OBSERVACIONES
B35: En octubre de 2025 la severidad alcanzó el 6,6 %, evidenciando una reducción en comparación con el 27,7 % registrado en octubre de 2024. Por su parte, en noviembre de 2025 la severidad alcanzó el 16,9 %, evidenciando un aumento en comparación con el 7,3 % registrado en noviembre de 2024.

Sheet 7. Inves. AT
D1: FORMATO
D2: FICHA TECNICA DEL INDICADOR
B5: PROCESO: | D5: Seguridad y salud en el trabajo | H5: RESPONSABLE: | J5: Johan Cartagena
B7: NOMBRE DEL INDICADOR | E7: Investigacion de accidentes de trabajo
B8: DEFINICION | E8: Numero de accidentes de trabajo investigados
B9: FORMULA | E9: (Numero de accidentes de trabajo investigados/Numero de accidentes de trabajo ocurridos)*100
B10: INTERPRETACION | E10: En el mes X se presentaron x accidentes de los cuales se investigaron el X%
B11: MECANISMO Y RESPONSABLE DE MEDICIÓN
B12: Jefe de proceso y Coordinador SGI, realizará el calculo y análisis
B13: PERSONAS QUE DEBEN CONOCER EL RESULTADO
B14: Director SG SST - Gestor de Seguridad - Incubadora Santander SA
B15: RESULTADOS
B16: VARIABLE | C16: Ene | D16: Feb | E16: Mar | F16: Abr | G16: May | H16: Jun | I16: Jul | J16: Ago | K16: Sept | L16: Oct | M16: Nov | N16: Dic | O16: Acum Año
B17: #AT | C17: 1 | D17: 5 | E17: 0 | F17: 1 | G17: 0 | H17: 2 | I17: 1 | J17: 4
B18: # AT INVE | C18: 1 | D18: 5 | E18: 0 | F18: 1 | G18: 0 | H18: 2 | I18: 1 | J18: 4
B19: CUMPLIMIENTO | C19: =C18/C17*100 -> 100 | D19: 5 | E19: 0 | F19: =F17/F18*100 -> 100 | G19: 0 | H19: =H17/H18*100 -> 100 | I19: =I17/I18*100 -> 100 | J19: =J17/J18*100 -> 100
B20: META | C20: 100 | D20: 100 | E20: 100 | F20: 100 | G20: 100 | H20: 100 | I20: 100 | J20: 100 | K20: 100 | L20: 100 | M20: 100
B21: GRÁFICO DE RESULTADO
B34: OBSERVACIONES

Sheet 9. Parte del cuerpo
A1: PARTE DEL CUERPO AFECTADA | B1: CANTIDAD | I1: PARTE DEL CUERPO AFECTADA | J1: CANTIDAD
A2: Manos | I2: Manos
A3: Pies | I3: Pies
A4: Miembros inferiores | I4: Miembros inferiores
A5: Miembros superiores | I5: Miembros superiores | J5: 1
A6: Ojo | B6: 1 | I6: Ojo
A7: Tronco (incluye espalda, columna vertebral, medula espinal, pelvis) | I7: Tronco (incluye espalda, columna vertebral, medula espinal, pelvis)
A8: Ubicaciones múltiples | I8: Ubicaciones múltiples
A9: Cabeza | I9: Cabeza
A10: Cuello | I10: Cuello
A11: Lesiones generales u otras | I11: Lesiones generales u otras
A12: TOTAL | I12: TOTAL
A14: PARTE DEL CUERPO AFECTADA | B14: CANTIDAD
A15: Manos
A16: Pies
A17: Miembros inferiores | B17: 1
A18: Miembros superiores
A19: Ojo
A20: Tronco (incluye espalda, columna vertebral, medula espinal, pelvis)
A21: Ubicaciones múltiples
A22: Cabeza | B22: 1
A23: Cuello
A24: Lesiones generales u otras
A25: TOTAL | B25: =SUM(B15:B24) -> 2
A27: PARTE DEL CUERPO AFECTADA | B27: CANTIDAD
A28: Manos
A29: Pies | B29: 1
A30: Miembros inferiores | B30: 1
A31: Miembros superiores | B31: 1
A32: Ojo
A33: Tronco (incluye espalda, columna vertebral, medula espinal, pelvis)
A34: Ubicaciones múltiples
A35: Cabeza | B35: 1
A36: Cuello
A37: Lesiones generales u otras
A38: TOTAL | B38: =SUM(B28:B37) -> 4
A41: PARTE DEL CUERPO AFECTADA | B41: CANTIDAD | I41: PARTE DEL CUERPO AFECTADA | J41: CANTIDAD
A42: Manos | I42: Manos
A43: Pies | B43: 1 | I43: Pies
A44: Miembros inferiores | B44: 1 | I44: Miembros inferiores | J44: 1
...

Sheet 10. Agente de lesion
A1: AGENTE DE LESION | B1: CANTIDAD | I1: AGENTE DE LESION | J1: CANTIDAD
A2: Aguja/material cortopunzante | I2: Aguja/material cortopunzante
A3: Ambiente de trabajo (incluye superficies de tránsito y de trabajo, muebles, tejados, en el exterior, interior o subterráneos) | I3: Ambiente de trabajo (incluye superficies de tránsito y de trabajo, muebles, tejados, en el exterior, interior o subterráneos)
A4: Animales (vivos o productos animales) | I4: Animales (vivos o productos animales)
A5: Herramientas, implementos o utensilios | I5: Herramientas, implementos o utensilios | J5: 1
A6: Maquinas y/o equipos | I6: Maquinas y/o equipos
A7: Materiales o sustancias | I7: Materiales o sustancias
A8: Otros agentes no clasificados | B8: 1 | I8: Otros agentes no clasificados
A9: TOTAL | I9: TOTAL
A11: AGENTE DE LESION | B11: CANTIDAD
A12: Aguja/material cortopunzante
A13: Ambiente de trabajo (incluye superficies de tránsito y de trabajo, muebles, tejados, en el exterior, interior o subterráneos) | B13: 1
A14: Animales (vivos o productos animales)
A15: Herramientas, implementos o utensilios
A16: Maquinas y/o equipos | B16: 1
A17: Materiales o sustancias
A18: Otros agentes no clasificados
A19: TOTAL | B19: =SUBTOTAL(109,B12:B18) -> 2
A21: AGENTE DE LESION | B21: CANTIDAD
A22: Aguja/material cortopunzante
A23: Ambiente de trabajo (incluye superficies de tránsito y de trabajo, muebles, tejados, en el exterior, interior o subterráneos) | B23: 1
A24: Animales (vivos o productos animales) | B24: 1
A25: Herramientas, implementos o utensilios | B25: 1
A26: Maquinas y/o equipos
A27: Materiales o sustancias | B27: 1
A28: Otros agentes no clasificados
A29: TOTAL | B29: =SUBTOTAL(109,B22:B28) -> 4
A32: AGENTE DE LESION | B32: CANTIDAD | I32: AGENTE DE LESION | J32: CANTIDAD
A33: Aguja/material cortopunzante | I33: Aguja/material cortopunzante
A34: Ambiente de trabajo (incluye superficies de tránsito y de trabajo, muebles, tejados, en el exterior, interior o subterráneos) | B34: 1 | I34: Ambiente de trabajo (incluye superficies de tránsito y de trabajo, muebles, tejados, en el exterior, interior o subterráneos) | J34: 1
A35: Animales (vivos o productos animales) | I35: Animales (vivos o productos animales)
A36: Herramientas, implementos o utensilios | B36: 2 | I36: Herramientas, implementos o utensilios
A37: Maquinas y/o equipos | B37: 2 | I37: Maquinas y/o equipos | J37: 1
A38: Materiales o sustancias | I38: Materiales o sustancias
A39: Otros agentes no clasificados | I39: Otros agentes no clasificados
A40: TOTAL | B40: =SUBTOTAL(109,B33:B39) -> 5 | I40: TOTAL
A43: AGENTE DE LESION | B43: CANTIDAD
A44: Aguja/material cortopunzante
A45: Ambiente de trabajo (incluye superficies de tránsito y de trabajo, muebles, tejados, en el exterior, interior o subterráneos)
A46: Animales (vivos o productos animales)
...

Sheet 8. Tipo de lesion
A1: TIPO DE LESION | B1: CANTIDAD
A2: Efecto del tiempo, del clima u otro relacionado con el ambiente | L2: TIPO DE LESION | M2: CANTIDAD
A3: Herida | L3: Efecto del tiempo, del clima u otro relacionado con el ambiente
A4: Lesiones múltiples | L4: Herida
A5: Fractura | L5: Lesiones múltiples
A6: Torcedura, esguince, desgarro muscular, hernia o laceración de musculo o tendón sin herida (25) | L6: Fractura
A7: Trauma superficial (incluye rasguño, punción o pinchazo y lesión en ojo por cuerpo extraño) | B7: 1 | L7: Torcedura, esguince, desgarro muscular, hernia o laceración de musculo o tendón sin herida (25)
A8: Golpe o contusión | L8: Trauma superficial (incluye rasguño, punción o pinchazo y lesión en ojo por cuerpo extraño)
A9: TOTAL | L9: Golpe o contusión
A11: TIPO DE LESION | B11: CANTIDAD
A12: Efecto del tiempo, del clima u otro relacionado con el ambiente
A13: Herida
A14: Lesiones múltiples
A15: Fractura
A16: Torcedura, esguince, desgarro muscular, hernia o laceración de musculo o tendón sin herida (25) | B16: 1
A17: Trauma superficial (incluye rasguño, punción o pinchazo y lesión en ojo por cuerpo extraño)
A18: Golpe o contusión
A19: TOTAL
A22: TIPO DE LESION | B22: CANTIDAD
A23: Efecto del tiempo, del clima u otro relacionado con el ambiente
A24: Herida
A25: Lesiones múltiples
A26: Fractura
A27: Torcedura, esguince, desgarro muscular, hernia o laceración de musculo o tendón sin herida (25) | B27: 1
A28: Trauma superficial (incluye rasguño, punción o pinchazo y lesión en ojo por cuerpo extraño)
A29: Golpe, contusión o aplaztamiento | B29: 2
A30: Envenenamiento o Intoxicación aguda o Alergia | B30: 1
A31: TOTAL | B31: =SUM(B23:B30) -> 4
A34: TIPO DE LESION | B34: CANTIDAD | K34: TIPO DE LESION | L34: CANTIDAD
A35: Efecto del tiempo, del clima u otro relacionado con el ambiente | K35: Efecto del tiempo, del clima u otro relacionado con el ambiente
A36: Herida | K36: Herida
A37: Lesiones múltiples | K37: Lesiones múltiples
A38: Fractura | K38: Fractura
A39: Torcedura, esguince, desgarro muscular, hernia o laceración de musculo o tendón sin herida (25) | B39: 1 | K39: Torcedura, esguince, desgarro muscular, hernia o laceración de musculo o tendón sin herida (25) | L39: 2
A40: Trauma superficial (incluye rasguño, punción o pinchazo y lesión en ojo por cuerpo extraño) | K40: Trauma superficial (incluye rasguño, punción o pinchazo y lesión en ojo por cuerpo extraño)
A41: Golpe, contusión o aplaztamiento | B41: 4 | K41: Golpe o contusión
A42: Envenenamiento o Intoxicación aguda o Alergia
A43: TOTAL | B43: =SUM(B35:B42) -> 5
A46: TIPO DE LESION | B46: CANTIDAD
A47: Efecto del tiempo, del clima u otro relacionado con el ambiente
...

Sheet 11. Mecanismo
A1: MECANISMO | B1: CANTIDAD
A2: Caída de objetos | I2: MECANISMO | J2: CANTIDAD
A3: Otro, cuerpo extraño en ojo | B3: 1 | I3: Caída de objetos
A4: Caída de personas | I4: Otro, corte | J4: 1
A5: Pisadas, choques o golpes | I5: Caída de personas
A6: Sobreesfuerzo, esfuerzo excesivo, o falso movimiento | I6: Pisadas, choques o golpes
A7: Atrapamientos | I7: Sobreesfuerzo, esfuerzo excesivo, o falso movimiento
A8: Contacto con mezcla de alimento | I8: Atrapamientos
A9: Exposición o contacto con líquidos de precaución universal (líquidos/ secreciones corporales) | I9: Contacto con mezcla de alimento
A10: Mordedura-picadura | I10: Exposición o contacto con líquidos de precaución universal (líquidos/ secreciones corporales)
A11: TOTAL | I11: Mordedura-picadura
I12: TOTAL
A13: MECANISMO | B13: CANTIDAD
A14: Caída de objetos
A15: Otro
A16: Caída de personas
A17: Pisadas, choques o golpes
A18: Sobreesfuerzo, esfuerzo excesivo, o falso movimiento | B18: 1
A19: Atrapamientos
A20: Contacto con mezcla de alimento
A21: Exposición o contacto con líquidos de precaución universal (líquidos/ secreciones corporales)
A22: Mordedura-picadura
A23: TOTAL
A25: MECANISMO | B25: CANTIDAD
A26: Caída de objetos
A27: Otro
A28: Caída de personas
A29: Pisadas, choques o golpes | B29: 1
A30: Sobreesfuerzo, esfuerzo excesivo, o falso movimiento | B30: 2
A31: Atrapamientos
A32: Contacto con mezcla de alimento
A33: Exposición o contacto con líquidos de precaución universal (líquidos/ secreciones corporales)
A34: Mordedura-picadura | B34: 1
A35: TOTAL | B35: =SUM(B26:B34) -> 4
A38: MECANISMO | B38: CANTIDAD
A39: Caída de objetos
A40: Otro
A41: Caída de personas
A42: Pisadas, choques o golpes
A43: Sobreesfuerzo, esfuerzo excesivo, o falso movimiento | B43: 2
...

Sheet 12.Cargo
A1: CARGO | B1: CANTIDAD | I1: CARGO | J1: CANTIDAD
A2: Auxiliar | I2: Auxiliar
A3: Auxiliar agricola | I3: Auxiliar agricola
A4: Operario de clasificacion | B4: 1 | I4: Operario de clasificacion | J4: 1
A5: Auxiliar de bodega | I5: Auxiliar de bodega
A6: Conductor | I6: Conductor
A7: Auxiliar de mantenimiento | I7: Auxiliar de mantenimiento
A8: TOTAL | I8: TOTAL
A10: CARGO | B10: CANTIDAD
A11: Auxiliar de cargue y descargue
A12: Auxiliar agricola
A13: Operario de granja | B13: 1
A14: Auxiliar de bodega
A15: Conductor
A16: Auxiliar de mantenimiento
A17: TOTAL
A19: CARGO | B19: CANTIDAD
A20: Auxiliar de cargue y descargue | B20: 1
A21: Auxiliar | B21: 2
A22: Operario | B22: 1
A23: Auxiliar de bodega
A24: Conductor
A25: Auxiliar de mantenimiento
A26: TOTAL | B26: =SUM(B20:B25) -> 4
A29: CARGO | B29: CANTIDAD
A30: Auxiliar de cargue y descargue | B30: 1
A31: Auxiliar
A32: Operario | B32: 1
A33: Auxiliar de bodega
A34: Conductor
A35: Auxiliar de mantenimiento
A36: TOTAL
A39: CARGO | B39: CANTIDAD
A40: Auxiliar de cargue y descargue
A41: Auxiliar
A42: Operario | B42: 1
A43: Auxiliar de bodega
A44: Conductor
A45: Auxiliar de mantenimiento
A46: TOTAL | B46: =SUM(B40:B45) -> 1
...

Sheet 13. Ejecu. PA
D1: FORMATO
D2: FICHA TECNICA DEL INDICADOR
B5: PROCESO: | D5: Seguridad y Salud en el Trabajo | H5: RESPONSABLE: | J5: Johan Cartagena
B7: NOMBRE DEL INDICADOR | E7: Cumplimiento cierre de planes de accion por AT
B8: DEFINICION | E8: NA
B9: FORMULA | E9: (Numero de planes de accion ejecutados / Numero de planes de accion planeados)*100
B10: INTERPRETACION | E10: NA
B11: MECANISMO Y RESPONSABLE DE MEDICIÓN
B12: Jefe de proceso y Coordinador SGI, realizará el calculo y análisis
B13: PERSONAS QUE DEBEN CONOCER EL RESULTADO
B14: Director SG SST - Gestor de Seguridad - Incubadora Santander SA
B15: RESULTADOS
B16: VARIABLE | C16: Ene | D16: Feb | E16: Mar | F16: Abr | G16: May | H16: Jun | I16: Jul | J16: Ago | K16: Sept | L16: Oct | M16: Nov | N16: Dic | O16: Acum Año
B17: # Plan Acc. Ejec. | C17: 1
B18: # Plan. Acc. Plan.
B19: CUMPLIMIENTO | C19: =C17/C18*100 -> #DIV/0! | D19: =D17/D18*100 -> #DIV/0! | E19: =E17/E18*100 -> #DIV/0! | F19: =F17/F18*100 -> #DIV/0! | G19: =G17/G18*100 -> #DIV/0! | H19: =H17/H18*100 -> #DIV/0! | I19: =I17/I18*100 -> #DIV/0! | J19: =J17/J18*100 -> #DIV/0! | ... N19: =N17/N18*100 -> #DIV/0!
B20: META | C20: 100 | D20: 100 | E20: 100 | F20: 100 | G20: 100 | H20: 100 | I20: 100 | J20: 100 | K20: 100 | L20: 100 | M20: 100 | N20: 100
B21: GRÁFICO DE RESULTADO
B34: OBSERVACIONES

Sheet 15. Ausentismo por EG
G2: PEGAR EN LA PRESENTACION MANTENIENDO EL MISMO FORMATO
A4: Mes | B4: Dias Ausentismo 2026 | C4: Dias Ausentismo 2025
A5: ENERO | B5: 179 | C5: 15
A6: FEBRERO | B6: 62 | C6: 64
A7: MARZO | B7: 96 | C7: 89
A8: ABRIL | B8: 193 | C8: 126
A9: MAYO | B9: 72 | C9: 156
A10: JUNIO | B10: 95 | C10: 116
A11: JULIO | B11: 52 | C11: 148
A12: AGOSTO | B12: 166 | C12: 40
A13: SEPTIEMBRE | C13: 57
A14: OCTUBRE | C14: 68
A15: NOVIEMBRE | C15: 91
A16: DICIEMBRE | C16: 111
A17: Total general | B17: =SUM(B5:B16) -> 915 | C17: =SUM(C5:C16) -> 1081
A26: MES | B26: ACTIVOS 2022 | C26: ACTIVOS 2023 | D26: DIFERENCIA | E26: R* 100 | F26: % REDUC/AUMENT | G26: ESTADO
A27: ENERO | B27: 57 | C27: 68 | D27: =C27-B27 -> 11 | E27: =D27*100 -> 1100 | F27: =E27/B27 -> 19.298246 | G27: =IF(J385=B27,"ESTABLE", IF(C27<B27,"BAJO",IF(C27>B27,"AUMENTO"))) -> AUMENTO
A28: FEBRERO | B28: 4310 | C28: 4724 | D28: =C28-B28 -> 414 | E28: =D28*100 -> 41400 | F28: =E28/B28 -> 9.6055684 | G28: =IF(J386=B28,"ESTABLE", IF(C28<B28,"BAJO",IF(C28>B28,"AUMENTO"))) -> AUMENTO
A29: MARZO | B29: 4276 | C29: 4983 | D29: =C29-B29 -> 707 | E29: =D29*100 -> 70700 | F29: =E29/B29 -> 16.534144 | G29: =IF(J387=B29,"ESTABLE", IF(C29<B29,"BAJO",IF(C29>B29,"AUMENTO"))) -> AUMENTO
A30: ABRIL | B30: 4422 | C30: 5149 | D30: =C30-B30 -> 727 | E30: =D30*100 -> 72700 | F30: =E30/B30 -> 16.440525 | G30: =IF(J388=B30,"ESTABLE", IF(C30<B30,"BAJO",IF(C30>B30,"AUMENTO"))) -> AUMENTO
A31: MAYO | B31: 4652 | C31: 5187 | D31: =C31-B31 -> 535 | E31: =D31*100 -> 53500 | F31: =E31/B31 -> 11.50043 | G31: =IF(J389=B31,"ESTABLE", IF(C31<B31,"BAJO",IF(C31>B31,"AUMENTO"))) -> AUMENTO
A32: JUNIO | B32: 4441 | C32: 5209 | D32: =C32-B32 -> 768 | E32: =D32*100 -> 76800 | F32: =E32/B32 -> 17.293402 | G32: =IF(J390=B32,"ESTABLE", IF(C32<B32,"BAJO",IF(C32>B32,"AUMENTO"))) -> AUMENTO
A33: JULIO | B33: 4365 | C33: 5313 | D33: =C33-B33 -> 948 | E33: =D33*100 -> 94800 | F33: =E33/B33 -> 21.718213 | G33: =IF(J391=B33,"ESTABLE", IF(C33<B33,"BAJO",IF(C33>B33,"AUMENTO"))) -> AUMENTO
A34: AGOSTO | B34: 4383 | C34: 5454 | D34: =C34-B34 -> 1071 | E34: =D34*100 -> 107100 | F34: =E34/B34 -> 24.435318 | G34: =IF(J392=B34,"ESTABLE", IF(C34<B34,"BAJO",IF(C34>B34,"AUMENTO"))) -> AUMENTO
A35: SEPTIEMBRE | B35: 4383 | C35: 5658 | D35: =C35-B35 -> 1275 | E35: =D35*100 -> 127500 | F35: =E35/B35 -> 29.089665 | G35: =IF(J393=B35,"ESTABLE", IF(C35<B35,"BAJO",IF(C35>B35,"AUMENTO"))) -> AUMENTO
A36: OCTUBRE | B36: 4855 | C36: 5888 | D36: =C36-B36 -> 1033 | E36: =D36*100 -> 103300 | F36: =E36/B36 -> 21.277034 | G36: =IF(J394=B36,"ESTABLE", IF(C36<B36,"BAJO",IF(C36>B36,"AUMENTO"))) -> AUMENTO
A37: NOVIEMBRE | B37: 4892 | C37: 6113 | D37: =C37-B37 -> 1221 | E37: =D37*100 -> 122100 | F37: =E37/B37 -> 24.959117 | G37: =IF(J395=B37,"ESTABLE", IF(C37<B37,"BAJO",IF(C37>B37,"AUMENTO"))) -> AUMENTO
A38: DICIEMBRE | B38: 4960 | C38: 5042 | D38: =C38-B38 -> 82 | E38: =D38*100 -> 8200 | F38: =E38/B38 -> 1.6532258 | G38: =IF(J396=B38,"ESTABLE", IF(C38<B38,"BAJO",IF(C38>B38,"AUMENTO"))) -> AUMENTO
A39: TOTAL FRECUENCI ACUMULADA | B39: =#REF! -> #REF! | C39: =#REF! -> #REF! | D39: =C39-B39 -> #REF! | E39: =D39*100 -> #REF! | F39: =E39/B39 -> #REF! | G39: =IF(J397=B39,"ESTABLE", IF(C39<B39,"BAJO",IF(C39>B39,"AUMENTO"))) -> #REF!

Sheet XXXXXXXXXXXXXXXX
C8: DIAGNOSTICOS | E8: DIAS
C9: FRACTURA DE LA DIAFISIS DE LA TIBIA | E9: 30
C10: FRACTURA DE LA EPIFISIS INFERIOR DEL RADIO | E10: 30
C11: LUXACION DE LA ARTICULACION DEL HOMBRO | E11: 30
C20: DIAGNOSTICO | D20: DIAS DE INCAPACIDAD
C21: HERIDA DE DEDO(S) DE LA MANO, SIN DANO DE LA(S) UNA(S) | D21: 10
C22: FRACTURA DE LA EPIFISIS INFERIOR DEL FEMUR | D22: 10
B45: 2025 | F45: 126 | G45: 156 | H45: 116 | I45: 148 | J45: 40 | K45: 57 | L45: 68 | M45: 91
B46: 2024 | C46: 162 | D46: 116 | E46: 103 | F46: 120 | G46: 180 | H46: 175 | I46: 191 | J46: 194 | K46: 125 | L46: 112
A47: 1 | B47: 2023 | C47: 106 | D47: 158 | E47: 149 | F47: 161 | G47: 153 | H47: 129 | I47: 127 | J47: 109 | K47: 112 | L47: 112 | M47: 81 | N47: 76
G50: 2024
G51: 162

Sheet A.T
E1: SEVERIDAD 2024 | F1: #REF! | G1: #REF! | H1: #REF! | J1: #REF! | K1: #REF! | L1: #REF! | M1: #REF! | N1: #REF! | O1: #REF! | P1: #REF! | Q1: #REF! | R1: #REF!
E14: NOMBRES Y APELLIDOS | F14: IDENTIFICACION | G14: LOCALIDAD | H14: ORIGEN | I14: PCL | J14: ESTADO ACTUAL
E15: SANTOS SILVA ARIEL RICARDO | F15: 1102354699 | G15: Bucaramanga | H15: ORIGEN COMUN ACCIDENTE DE TRANSITO | I15: N/A
E16: LEYDER PEREZ CAMPO | F16: 1096183241 | G16: Bucaramanga | H16: ACCIDENTE DE TRABAJO | I16: N/A
E17: JHON FREDDY ESCOBAR GOMEZ | F17: 91185598 | G17: Bucaramanga | H17: ACCIDENTE DE TRABAJO | I17: N/A
E18: RODRÍGUEZ MANRIQUE PEDRO ELIAS | F18: 91536229 | G18: Bucaramanga | H18: ACCIDENTE DE TRABAJO | I18: N/A
E19: HERNANDO NICOLAS LARA RODRIGUEZ | F19: 1098797707 | G19: Bucaramanga | H19: ORIGEN COMUN ACCIDENTE DE TRANSITO | I19: N/A
E21: NOMBRES Y APELLIDOS | F21: IDENTIFICACION | G21: LOCALIDAD | H21: ORIGEN | I21: PCL | J21: ESTADO ACTUAL
E22: FRANCISCO JAVIER ANGULO GONZALEZ | F22: 1149687009 | G22: CALOTO | H22: ACCIDENTE DE TRABAJO | I22: 0 | J22: AGOSTO: Aun la eps no le ha programado cita, se instauro PQR a la super salud y un no han dado respuesta. Adionalmente presentó un accidente de transito por el cual le generaron incapacidad
E23: CARLOS ARTURO SIERRA LOPEZ | F23: 12748783 | G23: PASTO | H23: ACCIDENTE DE TRABAJO | I23: 0 | J23: AGOSTO: Pendiente cita con neurocirijno para revisar la electromiografia que le fue realizda
E24: BANGUERO VILLEGAS JHON JANER | F24: 1061435198 | G24: CALOTO | I24: 0 | J24: AGOSTO:RM de hombro evidencia lesión del deltoides. En control de ortopedia (06/07) indican manejo quirúrgico por lesiones Hill-Sachs y Bankart, persiste omalgia izquierda. Remiten a medicina laboral, ortopedia y medicina física/RH. Sin cirugía programada a la fecha. Antecedente de luxación de hombro izquierdo en 2016; ARL solicitó HC de últimos 5 años, entregadas oportunamente. PCL: 0%; se desconoce apelación. Última incapacidad finalizó el 04/09.
E25: MINA PAZ LEYDER | F25: 76046337 | G25: CALOTO | H25: ORIGEN COMUN ACCIDENTE DE TRANSITO | I25: N/A | J25: AGOSTO: El colaborador estuvo incapacitado durante todo el mes de agosto. actualmente, la vigencia de la incapacidad va hasta el 10 de septiembre.
E27: NOMBRES Y APELLIDOS | F27: FECHA A.T. | G27: LOCALIDAD | H27: ORIGEN | I27: DIAGNOSTICO Y DIAS DE INCAPACIDAD | J27: ESTADO ACTUAL
